Workbook

Sheet Base de Dados
A1: TABELA GERAL DE REGISTROS
A2: Nº REGISTRO | B2: VIGÊNCIA | C2: DATA | D2: MODALIDADE | E2: NOME INSTITUCIONAL | F2: NOME FANTASIA | G2: CNPJ Matriz | H2: CNPJ Filial | I2: PROGRAMA | J2: RES | K2: CONVÊNIO | L2: ENDEREÇO DO PROGRAMA | M2: CEP | N2: BAIRRO | O2: SUBPREFEITURA | P2: REGIÃO | Q2: TELEFONE | R2: E-MAIL | S2: SITE | T2: CAPACIDADE | U2: ATENDIDOS | V2: SEI | W2: Para encerramento | X2: ID
A3: 001/12 | B3: 4 (quatro) anos | C3: 46705 | D3: OSC | E3: ASSOCIAÇÃO SANTO AGOSTINHO - ASA | F3: CDI LAR SANTO ALBERTO | G3: 62.272.497/0001-54 | H3: 62.272.497/0010-45 | I3: CDI | J3: 9 | K3: SMADS | L3: Rua Professor Dorival Dias Minhoto, n° 231 | M3: 02435-090 | N3: Santana | O3: Santana/Tucuruvi | P3: Norte | Q3: (11) 2236-1418 | R3: asa@asatransforma.org.br | S3: www.asatransforma.org.br | T3: 31 | U3: 31 | V3: 6074.2023/0009887-0 | X3: 1
A4: 001.2/12 | B4: NÃO RENOVADO | C4: 46036 | D4: OSC | E4: ASSOCIAÇÃO SANTO AGOSTINHO - ASA | F4: INCLUSÃO DIGITAL PARA PESSOAS IDOSAS | G4: 62.272.497/0001-54 | H4: 62.272.497/0001-54 | I4: PROJETOS | J4: 12 | K4: FMID | L4: Professor Dorival Dias Minhoto, 231 | N4: Lausane Paulista | O4: Santana/Tucuruvi | P4: Norte | R4: thais.certain@asatrasnforma.org.br | S4: www.asatransforma.org.br | T4: 36 | U4: 36 | V4: 6074.2023/0009887-0 | X4: 2
A5: 002/12 | B5: NÃO RENOVADO | C5: 43390 | D5: OSC | E5: ASSOCIAÇÃO DOS FAMILIARES E AMIGOS DOS IDOSOS - AFAI | G5: 07.852.256/0001-76 | I5: CDI | O5: Vila Mariana | P5: Sul | R5: afaicdi@hotmail.com | X5: 3
A6: 003.1/12 | B6: 2 (dois) anos | C6: 46675 | D6: OSC | E6: ASSOCIAÇÃO FRANCISCANA DE SOLIDARIEDADE | F6: CASA DE CLARA | G6: 11.861.086/0001-63 | H6: 11.861.086/0013-05 | I6: NCI | J6: 8 | K6: Não | L6: Rua Serra de Jairé, n° 316 | M6: 03175-010 | N6: Belém | O6: Mooca | P6: Leste | Q6: (11) 2604-5688 | R6: sefras@sefras.org.br | S6: www.sefras.org.br | T6: 200 | U6: 170 | V6: 6074.2025/0007896-2 | X6: 4
A7: 003.2/12 | B7: NÃO RENOVADO | C7: 45802 | D7: OSC | E7: ASSOCIAÇÃO FRANCISCANA DE SOLIDARIEDADE - SEFRAS | F7: CASA DE CLARA | G7: 11.861.086/0001-63 | I7: CDI | J7: 9 | K7: SMADS | L7: Rua Serra de Jairé, n° 316 | M7: 03175-010 | N7: Belém | O7: Mooca | P7: Leste | Q7: 2604-5688 | R7: articulacao@sefras.org.br | S7: www.sefras.org.br | T7: 30 | U7: 29 | V7: Não possui | X7: 5
A8: 004.1/13 | B8: 4 (quatro) anos | C8: 47090 | D8: OSC | E8: SOCIEDADE BENEFICENTE EQUILIBRIO DE INTERLAGOS - SOBEI | F8: NCI IMBUIAS | G8: 53.818.191/0001-60 | H8: 53.818.191/0011-31 | I8: NCI | J8: 7 | K8: SMADS | L8: Rua Santo Antônio do Cântaro, 32 | M8: 04829-090 | N8: Jardim Bela Vista | O8: Capela do Socorro | P8: Sul | Q8: (11) 5973-6034 | R8: sobei@sobei.org.com.br | S8: www.sobei.org.br | T8: 200 | U8: 200 | V8: 6074.2024/0009788-4 | X8: 6
A9: 004.2/13 | B9: NÃO RENOVADO | C9: 43820 | D9: OSC | E9: SOCIEDADE BENEFICENTE EQUILIBRIO DE INTERLAGOS - SOBEI | F9: MONTANARO | G9: 53.818.191/0001-60 | H9: 53.818.191/0007-55 | I9: NCI | O9: Capela do Socorro | P9: Sul | R9: sobei@sobei.org.br | S9: www.sobei.org.br | X9: 7
A10: 004.3/13 | B10: NÃO RENOVADO | C10: 45643 | D10: OSC | E10: SOCIEDADE BENEFICENTE EQUILIBRIO DE INTERLAGOS - SOBEI | G10: 53.818.191/0001-60 | H10: 53.818.191/0020-22 | I10: ILPI | O10: Parelheiros | P10: Sul | R10: sobei@sobei.org.br | S10: www.sobei.org.br | X10: 8
A11: 004.4/13 | B11: 4 (quatro) anos | C11: 46582 | D11: OSC | E11: SOCIEDADE BENEFICENTE EQUILIBRIO DE INTERLAGOS - SOBEI | F11: CCINTER ANTONIO CARLOS CARUSO | G11: 53.818.191/0001-60 | H11: 53.818.191/0023-75 | I11: CCINTER | J11: 11 | K11: SMADS | L11: Rua Angelina Regolim Cardoso de Mendonça, n° 51 | M11: 04811-150 | N11: Jardim Régis | O11: Capela do Socorro | P11: Sul | Q11: (11) 5666-0242 | R11: sobei@sobei.org.br | S11: www.sobei.org.br | T11: 240 | U11: 240 | V11: 6074.2023/0006498-4 | X11: 9
A12: 005/13 | B12: NÃO RENOVADO | C12: 43820 | D12: OSC | E12: INSTITUTO SOCIAL, EDUCATIVO E BENEFICENTE NOVO SIGNO | G12: 78.636.974-0004-04 | I12: NCI | O12: Vila Mariana | P12: Sul | R12: msemanovosigno@uol.com.br | X12: 10
A13: 006/13 | B13: 4 (quatro) anos | C13: 46320 | D13: Particular | E13: PENSÃO NEW HEAVEN LTDA | F13: CASA DE REPOUSO NEW HEAVEN | G13: 02.345.462/0001-76 | I13: ILPI | J13: 3 | K13: Não | L13: Av Diogenes Ribeiro de Lima, 1768 | M13: 05.458-001 | N13: Alto de Pinheiros | O13: Pinheiros | P13: Oeste | Q13: (11) 3022-3902 | R13: contato.newheavenresidencialsr@gmail.com | S13: www.newheavenresidencialsenior.com | T13: 21 | U13: 17 | V13: 6074.2022/0007128-8 | X13: 11
A14: 007/13 | B14: 2 (dois) anos | C14: 46389 | D14: OSC | E14: ASSOCIAÇÃO DE ASSISTÊNCIA À CRIANÇA DEFICIENTE | F14: REABILITAÇÃO PARA IDOSOS COM DEFICIÊNCIA FÍSICA | G14: 60.979.457/0001-11 | H14: 60.979.457/0001-11 | I14: PROJETOS | J14: 12 | K14: Não | L14: Rua Professor Ascendino Reis, 724 | M14: 04027-000 | N14: Vila Clementino | O14: Vila Mariana | P14: Sul | Q14: (11) 5576-0769 | R14: prestacaodecontas@aacd.org.br | S14: www.aacd.org.br | T14: 7000 | U14: 900 | V14: 6074.2022/0007575-5 | X14: 12
A15: 008/13 | B15: 4 (quatro) anos | C15: 47268 | D15: Particular | E15: CASA DE REPOUSO RECANTO DAS ARAUCÁRIAS LTDA | F15: RESIDENCIAL DAS ARAUCÁRIAS | G15: 54.232.381/0001-63 | H15: 54.232.381/0001-63 | I15: ILPI | J15: 3 | K15: Não | L15: Rua dos Lírios, n° 282 | M15: 04047-040 | N15: Mirandópolis | O15: Vila Mariana | P15: Sul | Q15: (11) 2275-3078 | R15: pauloievorlino@terra.com.br | T15: 20 | U15: 18 | V15: 6074.2025/0003802-2 | X15: 13
A16: 009/13 | B16: 4 (quatro) anos | C16: 47315 | D16: OSC | E16: CENTRO DE PROMOÇÃO HUMANA LAR VICENTINO | F16: LAR VICENTINO | G16: 48.956.742/0001-11 | H16: 48.956.742/0001-11 | I16: ILPI | J16: 6 | K16: Não | L16: Rua Ovídio Lopes, n° 253 | M16: 03804-110 | N16: Ermelino Matarazzo | O16: Ermelino Matarazzo | P16: Leste | Q16: (11) 2546-5682 | R16: adminsitracao@larvicentino.org.br | S16: www.larvicentino.org.br | T16: 40 | U16: 35 | V16: 6074.2025/0005703-5 | X16: 14
A17: 010/13 | B17: 4 (quatro) anos | C17: 46980 | D17: Particular | E17: UNIGER - UNIDADE DE INTERNAÇÃO GERIÁTRICA LTDA | F17: RESIDENCIAL TONIOLO MEMORY CARE | G17: 07.463.596/0001-05 | H17: 07.463.596/0001-05 | I17: ILPI | J17: 3 | K17: Não | L17: Rua Dona Brígida, 671 | M17: 04111-081 | N17: Vila Mariana | O17: Vila Mariana | P17: Sul | Q17: (11) 3663-9060 / (11) 99316-6700 | R17: enfermeira.karen@residencialtoniolo.com.br | S17: www.residencialtoniolo.com.br | T17: 40 | U17: 37 | V17: 6074.2024/0006897-3 | W17: 6074.2022/0003144-8 | X17: 15
A18: 011/14 | B18: 2 (dois) anos | C18: 46359 | D18: OSC | E18: SINDICATO NACIONAL DOS APOSENTADOS, PENSIONISTAS E IDOSOS DA FORÇA SINDICAL | F18: CENTRO DE CONVIVÊNCIA, CIDADANIA E DEFESA DE DIREITOS DA PESSOA IDOSA | G18: 04.040.532/0001-03 | H18: 04.040.532/0001-03 | I18: PROJETOS | J18: 12 | K18: Não | L18: Rua do Carmo, 171 | M18: 01019-020 | N18: Sé | O18: Sé | P18: Centro | Q18: (11) 3293-7500 | R18: presidente@sindicatodosaposentados.org.br | S18: www.sindicatodosaposentados.org.br | T18: 84000 | U18: 50000 | V18: 6074.2024/0009788-4 | X18: 16
A19: 012.1/14 | B19: 4 (quatro) anos | C19: 47642 | D19: Particular | E19: CASA DE REPOUSO PARA IDOSOS RESIDENCIAL HARMONIA LTDA. | F19: RESIDENCIAL HARMONIA | G19: 07.403.676/0001-75 | H19: 07.403.676/0001-75 | I19: ILPI | J19: 3 | K19: Não | L19: Rua Conde de Porto Alegre, 1855 | M19: 04608-003 | N19: Campo Belo | O19: Santo Amaro | P19: Sul | Q19: (11) 5042-0858 | R19: juliane@residencialharmonia.com.br | S19: www.residencialharmonia.com.br | T19: 23 | U19: 18 | V19: 6074.2022/0000275-8 | X19: 17
A20: 012.2/14 | B20: NÃO RENOVADO | C20: 42471 | D20: Particular | E20: CASA DE REPOUSO PARA IDOSOS RESIDENCIAL HARMONIA LTDA. UNIDADE II (FILIAL) | G20: 07.403.676/0001-75 | I20: ILPI | J20: 3 | K20: Não | O20: Santo Amaro | P20: Sul | R20: contato@residencialharmonia.com.br | X20: 18
A21: 013/14 | B21: 2 (dois) anos | C21: 46478 | D21: Particular | E21: RECANTO DO IDOSO ANHANGUERA LTDA | F21: RECANTO DO IDOSO ANHANGUERA | G21: 04.256.978/0001-70 | H21: 04.256.978/0001-70 | I21: ILPI | J21: 3 | K21: Não | L21: Rod. Anhanguera, KM 21.5 | M21: 05275-000 | N21: Perus | O21: Perus/Anhanguera | P21: Norte | Q21: (11) 5198-4168 | R21: idoso@recantodoidoso.com.br | S21: www.recantodoidoso.com.br | T21: 26 | U21: 21 | V21: 6074.2023/0001561-4 | X21: 19
A22: 014/14 | B22: NÃO RENOVADO | C22: 45186 | D22: Particular | E22: SOLAR PRIMAVERA S/S LTDA - ME | G22: 03.671.916/0001-61 | I22: ILPI | J22: 3 | K22: Não | O22: Vila Maria/Vila Guilherme | P22: Norte | R22: helenaportugal@ibest.com.br | X22: 20
A23: 015.1/14 | B23: 4 (quatro) anos | C23: 47615 | D23: Particular | E23: MARLENE DE FÁTIMA MENDES | F23: CASA DE REPOUSO PÔR DO SOL | G23: 72.815.863/0001-28 | H23: 72.815.863/0001-28 | I23: ILPI | J23: 3 | K23: Não | L23: Rua Décio Reis, 492 | M23: 05446-010 | N23: Alto de Pinheiros | O23: Pinheiros | P23: Oeste | Q23: (11) 3814-6643 | R23: contato@casaderepousopordosol.com.br | S23: www.casaderepousopordosol.com.br | T23: 30 | U23: 26 | V23: 6074.2021/0008537-6 | X23: 21
A24: 015.2/14 | B24: 4 (quatro) anos | C24: 47026 | D24: Particular | E24: MARLENE DE FÁTIMA MENDES - EPP | F24: CASA DE REPOUSO ELITE | G24: 72.815.863/0001-28 | H24: 72.815.863/0002-09 | I24: ILPI | J24: 3 | K24: Não | L24: Rua Doutor Franco da Rocha, 50 | M24: 05015-040 | N24: Perdizes | O24: Lapa | P24: Oeste | Q24: (11) 3862-7836 | R24: fernandaprizon@ig.com.br | S24: www.casaderepousoelite | T24: 30 | U24: 26 | V24: 6074.2024/0007807-3 | X24: 22
A25: 016/14 | B25: 4 (quatro) anos | C25: 46848 | D25: Particular | E25: ALVORADA NOVA CASA DE REPOUSO LTDA | G25: 17.569.752/0001-70 | H25: 17.569.752/0001-70 | I25: ILPI | J25: 3 | K25: Não | L25: Rua Nova Jerusalém, n° 504 | M25: 03410-000 | N25: Tatuapé | O25: Mooca | P25: Leste | Q25: (11) 3895-0746 | R25: e.amorim.ribeiro@bol.com.br | T25: 23 | U25: 21 | V25: 6074.2024/0003245-6 | X25: 23
A26: 017/14 | B26: NÃO RENOVADO | C26: 44786 | D26: Particular | E26: RESIDENCIAL ALTO DA BOA VISTA PARA IDOSOS LTDA - ME | G26: 10.248.923/0001-10 | I26: ILPI | J26: 3 | K26: Não | O26: Santo Amaro | P26: Sul | R26: crirahal@ig.com.br | X26: 24
A27: 018/14 | B27: NÃO RENOVADO | C27: 44844 | D27: Particular | E27: UNIDADE GERONTOLÓGICA FERREIRA LTDA - ME - UNIDADE I | G27: 06.997.875/0001-96 | I27: ILPI | J27: 3 | K27: Não | L27: Rua Tirana, 26 | M27: 03.359-110 | N27: Vila Formosa | O27: Aricanduva/Formosa/Carrão | P27: Leste | Q27: (11) 2674 9131 | R27: ugf@ugerontologica.com.br | X27: 25
A28: 018/14 | B28: NÃO RENOVADO | C28: 42582 | D28: Particular | E28: UNIDADE GERONTOLÓGICA FERREIRA LTDA - ME - UNIDADE II (FILIAL) | G28: 06.997.875/0002-77 | I28: ILPI | J28: 3 | K28: Não | N28: Vila Formosa | O28: Aricanduva/Formosa/Carrão | P28: Leste | Q28: (11) 2674-9131 | R28: ugf@ugerontologica.com.br | X28: 26
A29: 019/14 | B29: 4 (quatro) anos | C29: 46617 | D29: Particular | E29: CASA DE REPOUSO LUZ DA MANHÃ SS LTDA | G29: 00.738.764/0001-89 | H29: 00.738.764/0001-89 | I29: ILPI | J29: 3 | K29: Não | L29: Rua Hugo Carotini, n° 567 | M29: 05532-020 | N29: Jd. Previdência | O29: Butantã | P29: Oeste | Q29: (11) 3721-3075 | R29: casaderepousoluzdamanha@gmail.com | T29: 15 | U29: 10 | V29: 6074.2023/0007539-0 | X29: 27
A30: 020.1/14 | B30: 4 (quatro) anos | C30: 46238 | D30: OSC | E30: CROPH - COORDENAÇÃO REGIONAL DAS OBRAS DE PROMOÇÃO HUMANA | F30: ILPI CANINDÉ | G30: 43.473.487/0001-32 | H30: 43.473.487/0021-86 | I30: ILPI | J30: 5 | K30: SMADS | L30: Rua Comendador Nestor Pereira, 77 | M30: 03.034-070 | N30: Pari | O30: Mooca | P30: Leste | Q30: (11) 3228-1873 | R30: adm.croph@gmail.com | S30: croph@uol.com.br | T30: 60 | U30: 53 | V30: 6074.2022/0005338-7 | X30: 28
A31: 020.2/14 | B31: 4 (quatro) anos | C31: 46238 | D31: OSC | E31: CROPH - COORDENAÇÃO REGIONAL DAS OBRAS DE PROMOÇÃO HUMANA | F31: ILPI SANTANA | G31: 43.473.487/0001-32 | H31: 43.473.487/0034-09 | I31: ILPI | J31: 5 | K31: SMADS | L31: Rua Capitão Sérvio Rodrigues Caldas, 143 | M31: 02.244-040 | N31: Parada Inglesa | O31: Santana/Tucuruvi | P31: Norte | Q31: (11) 2337-0704 | S31: croph@uol.com.br | T31: 30 | U31: 30 | V31: 6074.2022/0005338-7 | X31: 29
A32: 020.3/14 | B32: NÃO RENOVADO | C32: 43906 | D32: OSC | E32: CROPH - COORDENAÇÃO REGIONAL DE OBRAS DE PROMOÇÃO HUMANA | F32: SÍTIO DAS ALAMEDAS | G32: 43.473.487/0001-32 | H32: 43.473.487/0020-03 | I32: CAEI | J32: 10 | K32: SMADS | O32: Sé | P32: Centro | S32: croph@uol.com.br | X32: 30
A33: 020.4/14 | B33: 4 (quatro) anos | C33: 46238 | D33: OSC | E33: CROPH - COORDENAÇÃO REGIONAL DAS OBRAS DE PROMOÇÃO HUMANA | F33: CRECI | G33: 43.473.487/0001-32 | H33: 43.473.487/0014-57 | I33: NCI | J33: 7 | K33: SMADS | L33: Rua Formosa, 215 | M33: 01.049-000 | N33: Anhangabaú | O33: Sé | P33: Centro | Q33: (11) 3258-4376 | S33: croph@uol.com.br | T33: 400 | U33: 524 | V33: 6074.2022/0005338-7 | X33: 31
A34: 020.5/14 | B34: 4 (quatro) anos | C34: 46889 | D34: OSC | E34: CROPH - COORDENAÇÃO REGIONAL DAS OBRAS DE PROMOÇÃO HUMANA | F34: ILPI TULIPAS MOOCA | G34: 43.473.487/0001-32 | H34: 43.473.487/0041-20 | I34: ILPI | J34: 5 | K34: SMADS | L34: Rua Florianópolis, n° 184 | M34: 03185-050 | N34: Mooca | O34: Mooca | P34: Leste | Q34: (11) 2606-6360 | R34: adm.croph@gmail.com | S34: croph@uol.com.br | T34: 30 | U34: 30 | V34: 6074.2024/0004543-4 | X34: 32
A35: 020.6/14 | B35: 4 (quatro) anos | C35: 47268 | D35: OSC | E35: CROPH - COORDENAÇÃO REGIONAL DAS OBRAS DE PROMOÇÃO HUMANA | F35: CAEI - CASA VERDE | G35: 43.473.487/0001-32 | H35: 43.473.487/0001-32 | I35: CAEI | J35: 10 | K35: SMADS | L35: Rua Antonio Vera Cruz, 213 | M35: 02555-010 | N35: Casa Verde | O35: Casa Verde/Cachoeirinha/Limão | P35: Norte | Q35: (11) 3955-2121/3965-6006 | R35: adm.croph@uol.com.br | S35: www.croph.org.br | T35: 60 | U35: 60 | V35: 6074.2025/0004066-3 | X35: 33
A36: 021/14 | B36: 2 (dois) anos | C36: 46512 | D36: OSC | E36: ASSOCIAÇÃO NIPO-BRASILEIRA DE ASSISTÊNCIA SOCIAL - ENKYO | F36: NÚCLEO DE CONVIVÊNCIA PARA IDOSOS | G36: 21.161.900/0001-90 | H36: 21.161.900/0001-90 | I36: NCI | J36: 8 | K36: Não | L36: Rua Fagundes, n° 121 - 3° andar | M36: 01508-030 | N36: Liberdade | O36: Sé | P36: Centro | Q36: (11) 3274-6518 | R36: social@enkyo.org.br | S36: www.enkyo.org.br | T36: 80 | U36: 330 | V36: 6074.2023/0003862-2 | X36: 34
A37: 022/14 | B37: 4 (quatro) anos | C37: 46477 | D37: Particular | E37: RELUZ HOSPEDAGEM PARA IDOSOS LTDA_x000D_ ANTIGO: RENATA LUCAS GIOSA HOSPEDAGEM PARA IDOSOS - ME | F37: LAR RESIDENCIAL RELUZ | G37: 08.364.900/0001-20 | H37: 08.364.900/0001-20 | I37: ILPI | J37: 3 | K37: Não | L37: Rua Franco Paulista, n° 181 | M37: 02332-030 | N37: Água Fria | O37: Santana/Tucuruvi | P37: Norte | Q37: (11) 2950-5497 | R37: residencialreluz@hotmail.com | T37: 28 | U37: 19 | V37: 6074.2023/0002783-3 | X37: 35
A38: 023/14 | B38: 4 (quatro) anos | C38: 1º/12/2027 | D38: OSC | E38: INSTITUTO BRASILEIRO FILHAS DE SÃO CAMILO | F38: INSTITUIÇÃO DE LONGA PERMANÊNCIA PARA IDOSOS SÃO CAMILO | G38: 12.920.752/0001-50 | H38: 12.920.752/0002-30 | I38: ILPI | J38: 6 | K38: Não | L38: Rua Adelino Bertoli, n° 139 | M38: 02241-120 | N38: Vl. Dom Pedro II | O38: Santana/Tucuruvi | P38: Norte | Q38: (11) 2973-0813 | R38: administracao@filhasdesaocamilo.com.br | S38: www.filhasdesaocamilo.com.br | T38: 80 | U38: 80 | V38: 6074.2023/0011032-3 | X38: 36
A39: 024/15 | B39: 4 (quatro) anos | C39: 46826 | D39: Particular | E39: CASA DE REPOUSO ANA NERY LTDA | F39: CASA DE REPOUSO ANA NERY | G39: 01.607.265/0001-15 | H39: 01.607.265/0001-15 | I39: ILPI | J39: 3 | K39: Não | L39: Rua Dr. Alberto Bentro, n° 742 | M39: 04750-001 | N39: Santo Amaro | O39: Santo Amaro | P39: Sul | Q39: (11) 5686-2215 | R39: casaderepousoananery@hotmail.com | S39: www.casaderepousoananery;com.br | T39: 27 | U39: 24 | X39: 37
A40: 025/15 | B40: 2 (dois) anos | C40: 46249 | D40: OSC | E40: ASSOCIAÇÃO BENEFICENTE DE AMPARO AO IDOSO CARENTE CAMINHO DA VIDA | F40: CAMINHO DA VIDA | G40: 03.692.295/0001-00 | H40: 03.692.295/0001-00 | I40: ILPI | J40: 6 | K40: Não | L40: Avenida Doutor Bernardino Brito Fonseca de Carvalho, 2257 | M40: 03535-000 | N40: Jardim Samara | O40: Penha | P40: Leste | Q40: (11) 2748-7811 / (11) 99990-0083 | R40: administração@abaic.com.br e abaic.caminhodavida@gmail.com | S40: www.abaic.com.br | T40: 20 | U40: 10 | V40: 6074.2022/0000732-6 | X40: 38
...

Sheet TOTAIS
B1: REGIÃO | C1: SUBPREFEITURA | D1: ILPI particular | E1: ILPI conveniada | F1: ILPI não conveniada | G1: CDI particular | H1: CDI conveniado | I1: NCI conveniado | J1: NCI não conveniado | K1: CAEI | L1: CCINTER | M1: TOTAL POR SUBPREF
B2: Leste | C2: Aricanduva/Formosa/Carrão | D2: 48 | E2: 0 | F2: 3 | G2: 0 | H2: 1 | I2: 0 | J2: 0 | K2: 0 | L2: 0 | M2: =SUM(D2:L2) -> 52
B3: Oeste | C3: Butantã | D3: 30 | E3: 0 | F3: 3 | G3: 0 | H3: 1 | I3: 1 | J3: 0 | K3: 0 | L3: 0 | M3: =SUM(D3:L3) -> 35
B4: Sul | C4: Campo Limpo | D4: 9 | E4: 1 | F4: 0 | G4: 0 | H4: 1 | I4: 7 | J4: 4 | K4: 0 | L4: 0 | M4: =SUM(D4:L4) -> 22
B5: Sul | C5: Capela do Socorro | D5: 23 | E5: 1 | F5: 3 | G5: 0 | H5: 1 | I5: 3 | J5: 0 | K5: 1 | L5: 1 | M5: =SUM(D5:L5) -> 33
B6: Norte | C6: Casa Verde/Cachoeirinha/Limão | D6: 9 | E6: 1 | F6: 0 | G6: 0 | H6: 1 | I6: 3 | J6: 2 | K6: 1 | L6: 0 | M6: =SUM(D6:L6) -> 17
B7: Sul | C7: Cidade Ademar | D7: 10 | E7: 0 | F7: 2 | G7: 0 | H7: 0 | I7: 2 | J7: 0 | K7: 1 | L7: 0 | M7: =SUM(D7:L7) -> 15
B8: Leste | C8: Cidade Tiradentes | D8: 0 | E8: 0 | F8: 0 | G8: 0 | H8: 1 | I8: 1 | J8: 0 | K8: 0 | L8: 0 | M8: =SUM(D8:L8) -> 2
B9: Leste | C9: Ermelino Matarazzo | D9: 3 | E9: 0 | F9: 1 | G9: 0 | H9: 1 | I9: 3 | J9: 1 | K9: 0 | L9: 0 | M9: =SUM(D9:L9) -> 9
B10: Norte | C10: Freguesia do Ó/Brasilândia | D10: 8 | E10: 1 | F10: 1 | G10: 0 | H10: 0 | I10: 0 | J10: 3 | K10: 0 | L10: 2 | M10: =SUM(D10:L10) -> 15
B11: Leste | C11: Guaianases | D11: 3 | E11: 0 | F11: 0 | G11: 0 | H11: 0 | I11: 2 | J11: 0 | K11: 0 | L11: 0 | M11: =SUM(D11:L11) -> 5
B12: Sul | C12: Ipiranga | D12: 24 | E12: 0 | F12: 0 | G12: 1 | H12: 1 | I12: 1 | J12: 4 | K12: 0 | L12: 0 | M12: =SUM(D12:L12) -> 31
B13: Leste | C13: Itaim Paulista | D13: 9 | E13: 1 | F13: 7 | G13: 0 | H13: 0 | I13: 4 | J13: 0 | K13: 0 | L13: 0 | M13: =SUM(D13:L13) -> 21
... B33: Leste | C33: Vila Prudente | D33: 19 | E33: 0 | F33: 1 | G33: 0 | H33: 0 | I33: 2 | J33: 3 | K33: 0 | L33: 0 | M33: =SUM(D33:L33) -> 25
C34: TOTAL | D34: =SUM(D2:D33) -> 671 | E34: =SUM(E2:E33) -> 15 | F34: =SUM(F2:F33) -> 48 | G34: =SUM(G2:G33) -> 6 | H34: =SUM(H2:H33) -> 22 | I34: =SUM(I2:I33) -> 70 | J34: =SUM(J2:J33) -> 32 | K34: =SUM(K2:K33) -> 18 | ... M34: =SUM(M2:M33) -> 887
B35: Atualização: 06/05/2026. Base de dados dos registros do Conselho Municipal de Direitos do Idoso da Cidade de São Paulo (CMI/SP). Larissa Rocha
B37: • ILPI - Instituição de Longa Permanência para Idosos
B38: • NCI - Núcleo de Convivência para Idosos
B39: • CDI - Centro Dia para o Idoso
B40: • CAEI - Centro de Acolhida Especial para Idosos
B41: • CCINTER - Centro de Convivência Intergeracional

Sheet Base02
B2: ='Base de Dados'!Y2:Y1392 -> 0 | C2: ='Base de Dados'!D1:D1095 -> MODALIDADE | D2: ='Base de Dados'!F2:F1098 -> NOME FANTASIA | E2: ='Base de Dados'!G2:G683 -> CNPJ Matriz | F2: ='Base de Dados'!I2:I683 -> PROGRAMA
B3: ='Base de Dados'!Y3:Y1393 -> 0 | C3: ='Base de Dados'!E2:E1392 -> ASSOCIAÇÃO SANTO AGOSTINHO - ASA | D3: ='Base de Dados'!F3:F1392 -> CDI LAR SANTO ALBERTO | E3: ='Base de Dados'!G3:G683 -> 62.272.497/0001-54 | F3: ='Base de Dados'!I3:I1098 -> CDI
B4: ='Base de Dados'!Y5:Y1394 -> #VALUE! | C4: ='Base de Dados'!E3:E1393 -> ASSOCIAÇÃO SANTO AGOSTINHO - ASA | D4: ='Base de Dados'!F5:F1393 -> #VALUE! | E4: ='Base de Dados'!G5:G1089 -> #VALUE! | F4: ='Base de Dados'!I5:I1095 -> #VALUE!
B5: ='Base de Dados'!Y6:Y1395 -> #VALUE! | C5: ='Base de Dados'!E5:E1394 -> ASSOCIAÇÃO DOS FAMILIARES E AMIGOS DOS IDOSOS - AFAI | D5: ='Base de Dados'!F6:F1394 -> #VALUE! | E5: ='Base de Dados'!G6:G1095 -> #VALUE! | F5: ='Base de Dados'!I6:I1392 -> #VALUE!
B6: ='Base de Dados'!Y7:Y1396 -> #VALUE! | C6: ='Base de Dados'!E6:E1395 -> ASSOCIAÇÃO FRANCISCANA DE SOLIDARIEDADE | D6: ='Base de Dados'!F7:F1395 -> #VALUE! | E6: ='Base de Dados'!G7:G1392 -> #VALUE! | F6: ='Base de Dados'!I7:I1393 -> #VALUE!
B7: ='Base de Dados'!Y8:Y1397 -> #VALUE! | C7: ='Base de Dados'!E7:E1396 -> ASSOCIAÇÃO FRANCISCANA DE SOLIDARIEDADE - SEFRAS | D7: ='Base de Dados'!F8:F1396 -> #VALUE! | E7: ='Base de Dados'!G8:G1393 -> #VALUE! | F7: ='Base de Dados'!I8:I1394 -> #VALUE!
B8: ='Base de Dados'!Y9:Y1398 -> #VALUE! | C8: ='Base de Dados'!E8:E1397 -> SOCIEDADE BENEFICENTE EQUILIBRIO DE INTERLAGOS - SOBEI | D8: ='Base de Dados'!F9:F1397 -> #VALUE! | E8: ='Base de Dados'!G9:G1394 -> #VALUE! | F8: ='Base de Dados'!I9:I1395 -> #VALUE!
B9: ='Base de Dados'!Y10:Y1399 -> #VALUE! | C9: ='Base de Dados'!E9:E1398 -> SOCIEDADE BENEFICENTE EQUILIBRIO DE INTERLAGOS - SOBEI | D9: ='Base de Dados'!F10:F1398 -> #VALUE! | E9: ='Base de Dados'!G10:G1395 -> #VALUE! | F9: ='Base de Dados'!I10:I1396 -> #VALUE!
B10: ='Base de Dados'!Y12:Y1400 -> #VALUE! | C10: ='Base de Dados'!E10:E1399 -> SOCIEDADE BENEFICENTE EQUILIBRIO DE INTERLAGOS - SOBEI | D10: ='Base de Dados'!F12:F1399 -> #VALUE! | E10: ='Base de Dados'!G12:G1396 -> #VALUE! | F10: ='Base de Dados'!I12:I1397 -> #VALUE!
B11: ='Base de Dados'!Y13:Y1401 -> #VALUE! | C11: ='Base de Dados'!E12:E1400 -> #VALUE! | D11: ='Base de Dados'!F13:F1400 -> #VALUE! | E11: ='Base de Dados'!G13:G1397 -> #VALUE! | F11: ='Base de Dados'!I13:I1398 -> #VALUE!
B12: ='Base de Dados'!Y14:Y1402 -> #VALUE! | C12: ='Base de Dados'!E13:E1401 -> #VALUE! | D12: ='Base de Dados'!F14:F1401 -> #VALUE! | E12: ='Base de Dados'!G14:G1398 -> #VALUE! | F12: ='Base de Dados'!I14:I1399 -> #VALUE!
B13: ='Base de Dados'!Y15:Y1403 -> #VALUE! | C13: ='Base de Dados'!E14:E1402 -> #VALUE! | D13: ='Base de Dados'!F15:F1402 -> #VALUE! | E13: ='Base de Dados'!G15:G1399 -> #VALUE! | F13: ='Base de Dados'!I15:I1400 -> #VALUE!
B14: ='Base de Dados'!Y16:Y1404 -> #VALUE! | C14: ='Base de Dados'!E15:E1403 -> #VALUE! | D14: ='Base de Dados'!F16:F1403 -> #VALUE! | E14: ='Base de Dados'!G16:G1400 -> #VALUE! | F14: ='Base de Dados'!I16:I1401 -> #VALUE!
B15: ='Base de Dados'!Y17:Y1405 -> #VALUE! | C15: ='Base de Dados'!E16:E1404 -> #VALUE! | D15: ='Base de Dados'!F17:F1404 -> #VALUE! | E15: ='Base de Dados'!G17:G1401 -> #VALUE! | F15: ='Base de Dados'!I17:I1402 -> #VALUE!
B16: ='Base de Dados'!Y18:Y1406 -> #VALUE! | C16: ='Base de Dados'!E17:E1405 -> #VALUE! | D16: ='Base de Dados'!F18:F1405 -> #VALUE! | E16: ='Base de Dados'!G18:G1402 -> #VALUE! | F16: ='Base de Dados'!I18:I1403 -> #VALUE!
B17: ='Base de Dados'!Y19:Y1407 -> #VALUE! | C17: ='Base de Dados'!E18:E1406 -> #VALUE! | D17: ='Base de Dados'!F19:F1406 -> #VALUE! | E17: ='Base de Dados'!G19:G1403 -> #VALUE! | F17: ='Base de Dados'!I19:I1404 -> #VALUE!
B18: ='Base de Dados'!Y20:Y1408 -> #VALUE! | C18: ='Base de Dados'!E19:E1407 -> #VALUE! | D18: ='Base de Dados'!F20:F1407 -> #VALUE! | E18: ='Base de Dados'!G20:G1404 -> #VALUE! | F18: ='Base de Dados'!I20:I1405 -> #VALUE!
B19: ='Base de Dados'!Y21:Y1409 -> #VALUE! | C19: ='Base de Dados'!E20:E1408 -> #VALUE! | D19: ='Base de Dados'!F21:F1408 -> #VALUE! | E19: ='Base de Dados'!G21:G1405 -> #VALUE! | F19: ='Base de Dados'!I21:I1406 -> #VALUE!
B20: ='Base de Dados'!Y22:Y1410 -> #VALUE! | C20: ='Base de Dados'!E21:E1409 -> #VALUE! | D20: ='Base de Dados'!F22:F1409 -> #VALUE! | E20: ='Base de Dados'!G22:G1406 -> #VALUE! | F20: ='Base de Dados'!I22:I1407 -> #VALUE!
B21: ='Base de Dados'!Y23:Y1411 -> #VALUE! | C21: ='Base de Dados'!E22:E1410 -> #VALUE! | D21: ='Base de Dados'!F23:F1410 -> #VALUE! | E21: ='Base de Dados'!G23:G1407 -> #VALUE! | F21: ='Base de Dados'!I23:I1408 -> #VALUE!
B22: ='Base de Dados'!Y24:Y1412 -> #VALUE! | C22: ='Base de Dados'!E23:E1411 -> #VALUE! | D22: ='Base de Dados'!F24:F1411 -> #VALUE! | E22: ='Base de Dados'!G24:G1408 -> #VALUE! | F22: ='Base de Dados'!I24:I1409 -> #VALUE!
... B31: ='Base de Dados'!Y33:Y1421 -> #VALUE! | C31: ='Base de Dados'!E32:E1420 -> #VALUE! | D31: ='Base de Dados'!F33:F1420 -> #VALUE! | E31: ='Base de Dados'!G33:G1417 -> #VALUE! | F31: ='Base de Dados'!I33:I1418 -> #VALUE!
B32: ='Base de Dados'!Y36:Y1422 -> #VALUE! | C32: ='Base de Dados'!E33:E1421 -> #VALUE! | D32: ='Base de Dados'!F36:F1421 -> #VALUE! | E32: ='Base de Dados'!G36:G1418 -> #VALUE! | F32: ='Base de Dados'!I36:I1419 -> #VALUE!
B33: ='Base de Dados'!Y37:Y1423 -> #VALUE! | C33: ='Base de Dados'!E36:E1422 -> #VALUE! | D33: ='Base de Dados'!F37:F1422 -> #VALUE! | E33: ='Base de Dados'!G37:G1419 -> #VALUE! | F33: ='Base de Dados'!I37:I1420 -> #VALUE!
B34: ='Base de Dados'!Y38:Y1424 -> #VALUE! | C34: ='Base de Dados'!E37:E1423 -> #VALUE! | D34: ='Base de Dados'!F38:F1423 -> #VALUE! | E34: ='Base de Dados'!G38:G1420 -> #VALUE! | F34: ='Base de Dados'!I38:I1421 -> #VALUE!
B35: ='Base de Dados'!Y39:Y1425 -> #VALUE! | C35: ='Base de Dados'!E38:E1424 -> #VALUE! | D35: ='Base de Dados'!F39:F1424 -> #VALUE! | E35: ='Base de Dados'!G39:G1421 -> #VALUE! | F35: ='Base de Dados'!I39:I1422 -> #VALUE!
B36: ='Base de Dados'!Y40:Y1426 -> #VALUE! | C36: ='Base de Dados'!E39:E1425 -> #VALUE! | D36: ='Base de Dados'!F40:F1425 -> #VALUE! | E36: ='Base de Dados'!G40:G1422 -> #VALUE! | F36: ='Base de Dados'!I40:I1423 -> #VALUE!
B37: ='Base de Dados'!Y41:Y1427 -> #VALUE! | C37: ='Base de Dados'!E40:E1426 -> #VALUE! | D37: ='Base de Dados'!F41:F1426 -> #VALUE! | E37: ='Base de Dados'!G41:G1423 -> #VALUE! | F37: ='Base de Dados'!I41:I1424 -> #VALUE!
B38: ='Base de Dados'!Y42:Y1428 -> #VALUE! | C38: ='Base de Dados'!E41:E1427 -> #VALUE! | D38: ='Base de Dados'!F42:F1427 -> #VALUE! | E38: ='Base de Dados'!G42:G1424 -> #VALUE! | F38: ='Base de Dados'!I42:I1425 -> #VALUE!
B39: ='Base de Dados'!Y43:Y1429 -> #VALUE! | C39: ='Base de Dados'!E42:E1428 -> #VALUE! | D39: ='Base de Dados'!F43:F1428 -> #VALUE! | E39: ='Base de Dados'!G43:G1425 -> #VALUE! | F39: ='Base de Dados'!I43:I1426 -> #VALUE!
B40: ='Base de Dados'!Y44:Y1430 -> #VALUE! | C40: ='Base de Dados'!E43:E1429 -> #VALUE! | D40: ='Base de Dados'!F44:F1429 -> #VALUE! | E40: ='Base de Dados'!G44:G1426 -> #VALUE! | F40: ='Base de Dados'!I44:I1427 -> #VALUE!
B41: ='Base de Dados'!Y45:Y1431 -> #VALUE! | C41: ='Base de Dados'!E44:E1430 -> #VALUE! | D41: ='Base de Dados'!F45:F1430 -> #VALUE! | E41: ='Base de Dados'!G45:G1427 -> #VALUE! | F41: ='Base de Dados'!I45:I1428 -> #VALUE!
B42: ='Base de Dados'!Y46:Y1432 -> #VALUE! | C42: ='Base de Dados'!E45:E1431 -> #VALUE! | D42: ='Base de Dados'!F46:F1431 -> #VALUE! | E42: ='Base de Dados'!G46:G1428 -> #VALUE! | F42: ='Base de Dados'!I46:I1429 -> #VALUE!
B43: ='Base de Dados'!Y47:Y1433 -> #VALUE! | C43: ='Base de Dados'!E46:E1432 -> #VALUE! | D43: ='Base de Dados'!F47:F1432 -> #VALUE! | E43: ='Base de Dados'!G47:G1429 -> #VALUE! | F43: ='Base de Dados'!I47:I1430 -> #VALUE!
B44: ='Base de Dados'!Y48:Y1434 -> #VALUE! | C44: ='Base de Dados'!E47:E1433 -> #VALUE! | D44: ='Base de Dados'!F48:F1433 -> #VALUE! | E44: ='Base de Dados'!G48:G1430 -> #VALUE! | F44: ='Base de Dados'!I48:I1431 -> #VALUE!
... B51: ='Base de Dados'!Y55:Y1441 -> #VALUE! | C51: ='Base de Dados'!E54:E1440 -> #VALUE! | D51: ='Base de Dados'!F55:F1440 -> #VALUE! | E51: ='Base de Dados'!G55:G1437 -> #VALUE! | F51: ='Base de Dados'!I55:I1438 -> #VALUE!
B52: ='Base de Dados'!Y57:Y1442 -> #VALUE! | C52: ='Base de Dados'!E55:E1441 -> #VALUE! | D52: ='Base de Dados'!F57:F1441 -> #VALUE! | E52: ='Base de Dados'!G57:G1438 -> #VALUE! | F52: ='Base de Dados'!I57:I1439 -> #VALUE!
B53: ='Base de Dados'!Y58:Y1443 -> #VALUE! | C53: ='Base de Dados'!E57:E1442 -> #VALUE! | D53: ='Base de Dados'!F58:F1442 -> #VALUE! | E53: ='Base de Dados'!G58:G1439 -> #VALUE! | F53: ='Base de Dados'!I58:I1440 -> #VALUE!
B54: ='Base de Dados'!Y59:Y1444 -> #VALUE! | C54: ='Base de Dados'!E58:E1443 -> #VALUE! | D54: ='Base de Dados'!F59:F1443 -> #VALUE! | E54: ='Base de Dados'!G59:G1440 -> #VALUE! | F54: ='Base de Dados'!I59:I1441 -> #VALUE!
B55: ='Base de Dados'!Y60:Y1445 -> #VALUE! | C55: ='Base de Dados'!E59:E1444 -> #VALUE! | D55: ='Base de Dados'!F60:F1444 -> #VALUE! | E55: ='Base de Dados'!G60:G1441 -> #VALUE! | F55: ='Base de Dados'!I60:I1442 -> #VALUE!
...

Sheet Plan1
A3: Rótulos de Linha
A4: 001/12
A5: Associação Santo Agostinho - ASA.
A6: 62.272.497/0001-54
A7: 0010/13
A8: UNIGER - Unidade de Internação Geriátrica LTDA
A9: 07.463.596/0001-05
A10: 0011/14
A11: Sindicato Nacional dos Aposentados, Pensionistas e Idosos da Força Sindical
A12: 04.040.532/0001-03
A13: 0012/14
A14: Casa de Repouso para Idosos Residencial Harmonia LTDA. - Unidade I
... A1201: Total geral

Sheet Plan4
A1: REGISTRO | B1: 0017/14
A3: Rótulos de Linha
A4: Residencial Alto da Boa Vista para Idosos LTDA - ME
A5: 10.248.923/0001-10
A6: Total geral

Sheet Serviços por Região
A3: Rótulos de Linha | B3: Contar de REGISTRO
A4: Centro | B4: 24
A5: Leste | B5: 126
A6: Leste | B6: 2
A7: Norte | B7: 74
A8: Oeste | B8: 54
A9: SEM EFEITO | B9: 1
A10: Sul | B10: 129
A11: Sul | B11: 4
A12: (vazio) | B12: 9
A13: CENTRO DIA | B13: 2
A14: EDEM CENTRO DE CONVIVÊNCIA E CENTRO DIA PARA IDOSOS LTDA | B14: 1
A15: (vazio) | B15: 1
... A20: Total Geral | B20: 423
